Traceback (most recent call last):
  File "/home/runner/micromamba/envs/regional-mom6-dev/lib/python3.11/site-packages/jupyter_core/utils/__init__.py", line 154, in wrapped
    asyncio.get_running_loop()
RuntimeError: no running event loop

During handling of the above exception, another exception occurred:

Traceback (most recent call last):
  File "/home/runner/micromamba/envs/regional-mom6-dev/lib/python3.11/site-packages/jupyter_cache/executors/utils.py", line 58, in single_nb_execution
    executenb(
  File "/home/runner/micromamba/envs/regional-mom6-dev/lib/python3.11/site-packages/nbclient/client.py", line 1319, in execute
    return NotebookClient(nb=nb, resources=resources, km=km, **kwargs).execute()
           ^^^^^^^^^^^^^^^^^^^^^^^^^^^^^^^^^^^^^^^^^^^^^^^^^^^^^^^^^^^^^^^^^^^^^
  File "/home/runner/micromamba/envs/regional-mom6-dev/lib/python3.11/site-packages/jupyter_core/utils/__init__.py", line 158, in wrapped
    return loop.run_until_complete(inner)
           ^^^^^^^^^^^^^^^^^^^^^^^^^^^^^^
  File "/home/runner/micromamba/envs/regional-mom6-dev/lib/python3.11/asyncio/base_events.py", line 654, in run_until_complete
    return future.result()
           ^^^^^^^^^^^^^^^
  File "/home/runner/micromamba/envs/regional-mom6-dev/lib/python3.11/site-packages/nbclient/client.py", line 709, in async_execute
    await self.async_execute_cell(
  File "/home/runner/micromamba/envs/regional-mom6-dev/lib/python3.11/site-packages/nbclient/client.py", line 1062, in async_execute_cell
    await self._check_raise_for_error(cell, cell_index, exec_reply)
  File "/home/runner/micromamba/envs/regional-mom6-dev/lib/python3.11/site-packages/nbclient/client.py", line 918, in _check_raise_for_error
    raise CellExecutionError.from_cell_and_msg(cell, exec_reply_content)
nbclient.exceptions.CellExecutionError: An error occurred while executing the following cell:
------------------
# testing the s3 credentials should be set up in the environment
# and should be none since it is open access
import boto3
creds = boto3.Session().get_credentials()
print("AWS credentials:", creds)
------------------


[31m---------------------------------------------------------------------------[39m
[31mModuleNotFoundError[39m                       Traceback (most recent call last)
[36mCell[39m[36m [39m[32mIn[20][39m[32m, line 3[39m
[32m      1[39m [38;5;66;03m# testing the s3 credentials should be set up in the environment[39;00m
[32m      2[39m [38;5;66;03m# and should be none since it is open access[39;00m
[32m----> [39m[32m3[39m [38;5;28;01mimport[39;00m[38;5;250m [39m[34;01mboto3[39;00m
[32m      4[39m creds = boto3.Session().get_credentials()
[32m      5[39m [38;5;28mprint[39m([33m"[39m[33mAWS credentials:[39m[33m"[39m, creds)

[31mModuleNotFoundError[39m: No module named 'boto3'

